<?xml version="1.0" ?>
<robot name="wheelchair_base">
  <joint name="wheelchair_base__link_0_JOINT_0" type="revolute">
    <parent link="wheelchair_base__link_0"/>
    <child link="wheelchair_base__link_1"/>
    <origin rpy="0 0 0" xyz="0.2473  0.30924 0.5"/>
    <axis xyz="1 0 0"/>
    <limit effort="-1.0" lower="-1.79769e+308" upper="1.79769e+308" velocity="-1.0"/>
  </joint>
  <joint name="wheelchair_base__link_0_JOINT_1" type="revolute">
    <parent link="wheelchair_base__link_0"/>
    <child link="wheelchair_base__link_1_clone"/>
    <origin rpy="0 0 0" xyz="0.75965 0.30724 0.5"/>
    <axis xyz="1 0 0"/>
    <limit effort="-1.0" lower="-1.79769e+308" upper="1.79769e+308" velocity="-1.0"/>
  </joint>
  <joint name="wheelchair_base__link_0_JOINT_2" type="revolute">
    <parent link="wheelchair_base__link_0"/>
    <child link="wheelchair_base__link_2_clone"/>
    <origin rpy="0 0 0" xyz="0.69882 0.88174 0.43379"/>
    <axis xyz="1 0 0"/>
    <limit effort="-1.0" lower="-1.79769e+308" upper="1.79769e+308" velocity="-1.0"/>
  </joint>
  <joint name="wheelchair_base__link_0_JOINT_3" type="revolute">
    <parent link="wheelchair_base__link_0"/>
    <child link="wheelchair_base__link_2"/>
    <origin rpy="0 0 0" xyz="0.30213 0.88032 0.43379"/>
    <axis xyz="1 0 0"/>
    <limit effort="-1.0" lower="-1.79769e+308" upper="1.79769e+308" velocity="-1.0"/>
  </joint>
  <link name="wheelchair_base__link_0">
    <inertial>
      <mass value="1"/>
      <origin rpy="0 0 0" xyz="0 0 0"/>
      <inertia ixx="0.166667" ixy="0" ixz="0" iyy="0.166667" iyz="0" izz="0.166667"/>
    </inertial>
    <collision name="wheelchair_base__collision">
      <origin rpy="0 0 0" xyz="0.50222 0.51562 0.5"/>
      <geometry>
        <box size="0.45 0.8 0.2"/>
      </geometry>
    </collision>
    <visual name="wheelchair_base__visual">
      <origin rpy="0 0 0" xyz="0.50222 0.51562 0.5"/>
      <geometry>
        <box size="0.45 0.8 0.2"/>
      </geometry>
    </visual>
  </link>
  <link name="wheelchair_base__link_1">
    <inertial>
      <mass value="1"/>
      <origin rpy="1.5707 0     0" xyz="0 0 0"/>
      <inertia ixx="0.145833" ixy="0" ixz="0" iyy="0.145833" iyz="0" izz="0.125"/>
    </inertial>
    <collision name="wheelchair_base__collision">
      <origin rpy="1.5707 0     1.5707" xyz="0 0 0"/>
      <geometry>
        <cylinder length="0.06" radius="0.165"/>
      </geometry>
    </collision>
    <visual name="wheelchair_base__visual">
      <origin rpy="1.5707 0     1.5707" xyz="0 0 0"/>
      <geometry>
        <cylinder length="0.06" radius="0.165"/>
      </geometry>
    </visual>
  </link>
  <link name="wheelchair_base__link_1_clone">
    <inertial>
      <mass value="1"/>
      <origin rpy="1.5707 0     0" xyz="0 0 0"/>
      <inertia ixx="0.145833" ixy="0" ixz="0" iyy="0.145833" iyz="0" izz="0.125"/>
    </inertial>
    <collision name="wheelchair_base__collision">
      <origin rpy="1.5707 0     1.5707" xyz="0 0 0"/>
      <geometry>
        <cylinder length="0.06" radius="0.165"/>
      </geometry>
    </collision>
    <visual name="wheelchair_base__visual">
      <origin rpy="1.5707 0     1.5707" xyz="0 0 0"/>
      <geometry>
        <cylinder length="0.06" radius="0.165"/>
      </geometry>
    </visual>
  </link>
  <link name="wheelchair_base__link_2">
    <inertial>
      <mass value="1"/>
      <origin rpy="0 0 0" xyz="0 0 0"/>
      <inertia ixx="0.1" ixy="0" ixz="0" iyy="0.1" iyz="0" izz="0.1"/>
    </inertial>
    <collision name="wheelchair_base__collision">
      <origin rpy="0 0 0" xyz="0 0 0"/>
      <geometry>
        <sphere radius="0.1"/>
      </geometry>
    </collision>
    <visual name="wheelchair_base__visual">
      <origin rpy="0 0 0" xyz="0 0 0"/>
      <geometry>
        <sphere radius="0.1"/>
      </geometry>
    </visual>
  </link>
  <link name="wheelchair_base__link_2_clone">
    <inertial>
      <mass value="1"/>
      <origin rpy="0 0 0" xyz="0 0 0"/>
      <inertia ixx="0.1" ixy="0" ixz="0" iyy="0.1" iyz="0" izz="0.1"/>
    </inertial>
    <collision name="wheelchair_base__collision">
      <origin rpy="0 0 0" xyz="0 0 0"/>
      <geometry>
        <sphere radius="0.1"/>
      </geometry>
    </collision>
    <visual name="wheelchair_base__visual">
      <origin rpy="0 0 0" xyz="0 0 0"/>
      <geometry>
        <sphere radius="0.1"/>
      </geometry>
    </visual>
  </link>
</robot>
